Workbook

Sheet Início
B2: RELATÓRIO FINANCEIRO 2026 — LOJA PLANETA ÁGUA
B3: Clique no nome de qualquer aba abaixo para ir direto até ela. Em toda aba há um link "← Início" para voltar.
B5: NÚMEROS DO ANO
B6: ENTRADAS (ANO) | C6: SAÍDAS DA LOJA (ANO) | D6: SOBRA FINAL (DEPOIS DO PRÓ-LABORE) | E6: A RECEBER | F6: DÍVIDA BB | G6: MARGEM FINAL DO ANO
B7: =Dashboard!A5 | C7: =Dashboard!C5 | D7: =Dashboard!E5 | E7: =Dashboard!I5 | F7: =Dashboard!K5 | G7: =Dashboard!G5
B9: SAÚDE FINANCEIRA DA LOJA (MÉDIA MENSAL)
B10: CUSTO FIXO MÉDIO/MÊS | C10: CUSTO VARIÁVEL MÉDIO/MÊS | D10: PRÓ-LABORE EDILÂNIA (ANO) | E10: PONTO DE EQUILÍBRIO (FAT. MÍN./MÊS) | F10: PRÓ-LABORE COMBINADO/MÊS | G10: SOBRA MÉDIA/MÊS DEPOIS DO PRÓ-LABORE
B11: ='DRE Simplificado'!O23 | C11: ='DRE Simplificado'!O10 | D11: =Dashboard!B53 | E11: ='Ponto de Equilíbrio'!B12 | F11: ='Ponto de Equilíbrio'!$B$10 | G11: ='Ponto de Equilíbrio'!B14
B13: COMECE AQUI — visão geral
B14: Dashboard | C14: Resumo do ano: entradas, saídas, lucro, insights automáticos e ranking de produtos.
B15: DRE Simplificado | C15: O resultado mês a mês, separando custo variável de custo fixo. Mostra se a operação se paga.
B17: DINHEIRO A ENTRAR E A SAIR
B18: Contas a Pagar e Receber | C18: Quem ainda deve para a loja e o que a loja ainda deve. Totais automáticos.
B19: Capital de Giro (BB) | C19: Contas da loja pagas com o empréstimo do Banco do Brasil e quanto falta devolver.
B21: PLANEJAMENTO
B22: Ponto de Equilíbrio | C22: Quanto precisa faturar por mês só para não ter prejuízo — e para lucrar o que quiser.
B23: Fluxo de Caixa Projetado | C23: Projeção do saldo de setembro a dezembro no ritmo atual.
B24: Reserva e Impostos
B25: Orçado vs Realizado | C25: Meta do mês contra o que realmente aconteceu, categoria por categoria.
B26: Precificação e Margem | C26: Quanto sobra de verdade em cada produto depois de custo, comissão, taxa e imposto.
B28: APOIO
B29: Conciliação Bancária | C29: Confere lançamento por lançamento contra o extrato do banco.
B30: Cadastro Clientes-Fornec | C30: Base única de nomes, documentos e contatos.
B32: LANÇAMENTOS MÊS A MÊS
B33: Jan 2026 | C33: Entradas pelas notas fiscais (XML do DigiSat) com cliente e produto · saídas do Livro Caixa
B34: Fev 2026 | C34: Entradas pelas notas fiscais (XML do DigiSat) com cliente e produto · saídas do Livro Caixa
B35: Mar 2026 | C35: Entradas pelas notas fiscais (XML do DigiSat) com cliente e produto · saídas do Livro Caixa
B36: Abr 2026 | C36: Entradas pelas notas fiscais (XML do DigiSat) com cliente e produto · saídas do Livro Caixa
B37: Mai 2026 | C37: Entradas pelas notas fiscais (XML do DigiSat) com cliente e produto · saídas do Livro Caixa
B38: Jun 2026 | C38: Entradas pelas notas fiscais (XML do DigiSat) com cliente e produto · saídas do Livro Caixa
B39: Jul 2026 | C39: Entradas pelas notas fiscais (XML do DigiSat) com cliente e produto · saídas do Livro Caixa
B40: Ago 2026 | C40: Lançamento manual, com forma de pagamento e taxa da máquina
B41: Set 2026 | C41: MÊS ATUAL — lançamento manual, com forma de pagamento e taxa da máquina
B42: Out 2026 | C42: Pronto para lançar
B43: Nov 2026 | C43: Pronto para lançar
B44: Dez 2026 | C44: Pronto para lançar
B46: Como usar no dia a dia
B47: 1. Lance cada venda e cada despesa na aba do mês (ex.: "Ago 2026") — uma linha por lançamento.
B48: 2. Venda ainda não paga: escolha "Aguardando Pagamento" na coluna Forma de Pagamento. Ela aparece sozinha no cartão A RECEBER e na aba Contas a Pagar e Receber.
B49: 3. Quando o cliente pagar, troque a forma de pagamento pelo método real. Todo o resto recalcula sozinho.
...

Sheet Dashboard
A1: DASHBOARD FINANCEIRO — LOJA DE FILTROS | 2026
A2: Jan–Dez: lançamentos das abas dos meses. Entradas = faturamento recebido (líquido de taxa de máquina e sem vendas pendentes); saídas = despesas da loja (sem o pró-labore e sem as contas pagas pelo Capital de Giro do BB). O pró-labore da Edilânia aparece separado e é descontado na coluna "Sobra final". Vendas ainda não recebidas ficam na tabela "Contas a Receber".
A3: ← Início
A4: ENTRADAS (ANO) | C4: SAÍDAS (ANO) | E4: SOBRA FINAL (DEPOIS DO PRÓ-LABORE) | G4: MARGEM FINAL DO ANO | I4: A RECEBER (ANO) | K4: DÍVIDA — CAPITAL DE GIRO (BB)
A5: =SUM(B24:B35) | C5: =SUM(C24:C35) | E5: =SUM(G24:G35) | G5: =IF(B36=0,0,G36/B36) | I5: =H46 | K5: ='Capital de Giro (BB)'!C5
A8: INSIGHTS AUTOMÁTICOS
A9: ="Melhor mês (sobra final, depois do pró-labore): "&INDEX(A24:A35,MATCH(MAX(G24:G35),G24:G35,0))&" ("&TEXT(MAX(G24:G35),"R$ #,##0.00")&")"
A10: ="Mês mais fraco (sobra final, depois do pró-labore): "&INDEX(A24:A35,MATCH(_xlfn.MINIFS(G24:G35,B24:B35,"<>0"),G24:G35,0))&" ("&TEXT(_xlfn.MINIFS(G24:G35,B24:B35,"<>0"),"R$ #,##0.00")&")"
A11: ="Meses que fecharam no negativo depois do pró-labore: "&COUNTIF(G24:G35,"<0")&" de "&COUNTIF(B24:B35,"<>0")&" meses com dados · pró-labore do ano: "&TEXT(F36,"R$ #,##0.00")&" (combinado: "&TEXT('Ponto de Equilíbrio'!$B$10,"R$ #,##0.00")&"/mês)"
A12: ="Total a receber (vendas pendentes Ago–Dez): "&TEXT(H46,"R$ #,##0.00")
A13: ="Atenção em Agosto: "&TEXT('Ago 2026'!L19,"R$ #,##0.00")&" de despesas da loja foram pagas com o empréstimo do Banco do Brasil e por isso NÃO entram nas Saídas acima. Sem esse alívio, o lucro de agosto seria "&TEXT(D31-'Ago 2026'!L19,"R$ #,##0.00")&". "&IF('Capital de Giro (BB)'!C5=0,"Esse valor já foi devolvido integralmente.","Esse valor ainda precisa ser devolvido.")
A14: ⚠ Limitações dos dados de origem (relatórios DigiSat/G6, não planilhas de fluxo de caixa):
A15: • O Livro Caixa não registra a forma de pagamento (dinheiro/cartão/Pix) de cada venda — por isso não há aba de 'Entradas por Forma de Pagamento' neste arquivo.
A16: • O relatório 'Itens vendidos' traz apenas totais agregados de Jan–Jul/2026 por produto, sem data nem cliente — não é possível vincular cada item a uma venda ou mês específico. Por isso os produtos aparecem apenas como referência anual no Dashboard, não em cada aba mensal.
A17: • 'Contas a pagar pendentes' vêm da Lista de Pagamentos (situação 'Pendente') e ainda não aparecem como saída no Livro Caixa, pois não foram pagas até 27/07/2026.
A18: • O saldo acumulado do Livro Caixa foi ignorado, conforme solicitado — os totais aqui são apenas de entradas e saídas de cada mês.
A19: • Este Dashboard é CAIXA (dinheiro que entrou e saiu de fato). A aba "DRE Simplificado" é COMPETÊNCIA (considera a despesa no mês em que ela ocorreu, inclusive as pagas pelo Capital de Giro). Por isso o lucro das duas abas não é igual — as duas estão certas, medem coisas diferentes.
A23: Mês | B23: Entradas (R$) | C23: Saídas (R$) | D23: Lucro da loja (R$) | E23: Margem da loja (%) | F23: Pró-labore Edilânia (R$) | G23: Sobra final (R$)
A24: Janeiro | B24: =SUMIF('Jan 2026'!A5:A500,"<>",'Jan 2026'!D5:D500)-SUMIF('Jan 2026'!A5:A500,"<>",'Jan 2026'!F5:F500)-'Jan 2026'!T5 | C24: ='Jan 2026'!L18-'Jan 2026'!L19 | D24: =B24-C24 | E24: =IF(B24=0,0,D24/B24) | F24: ='Jan 2026'!L17 | G24: =D24-F24
A25: Fevereiro | B25: =SUMIF('Fev 2026'!A5:A500,"<>",'Fev 2026'!D5:D500)-SUMIF('Fev 2026'!A5:A500,"<>",'Fev 2026'!F5:F500)-'Fev 2026'!T5 | C25: ='Fev 2026'!L18-'Fev 2026'!L19 | D25: =B25-C25 | E25: =IF(B25=0,0,D25/B25) | F25: ='Fev 2026'!L17 | G25: =D25-F25
A26: Março | B26: =SUMIF('Mar 2026'!A5:A500,"<>",'Mar 2026'!D5:D500)-SUMIF('Mar 2026'!A5:A500,"<>",'Mar 2026'!F5:F500)-'Mar 2026'!T5 | C26: ='Mar 2026'!L18-'Mar 2026'!L19 | D26: =B26-C26 | E26: =IF(B26=0,0,D26/B26) | F26: ='Mar 2026'!L17 | G26: =D26-F26
A27: Abril | B27: =SUMIF('Abr 2026'!A5:A500,"<>",'Abr 2026'!D5:D500)-SUMIF('Abr 2026'!A5:A500,"<>",'Abr 2026'!F5:F500)-'Abr 2026'!T5 | C27: ='Abr 2026'!L18-'Abr 2026'!L19 | D27: =B27-C27 | E27: =IF(B27=0,0,D27/B27) | F27: ='Abr 2026'!L17 | G27: =D27-F27
A28: Maio | B28: =SUMIF('Mai 2026'!A5:A500,"<>",'Mai 2026'!D5:D500)-SUMIF('Mai 2026'!A5:A500,"<>",'Mai 2026'!F5:F500)-'Mai 2026'!T5 | C28: ='Mai 2026'!L18-'Mai 2026'!L19 | D28: =B28-C28 | E28: =IF(B28=0,0,D28/B28) | F28: ='Mai 2026'!L17 | G28: =D28-F28
A29: Junho | B29: =SUMIF('Jun 2026'!A5:A500,"<>",'Jun 2026'!D5:D500)-SUMIF('Jun 2026'!A5:A500,"<>",'Jun 2026'!F5:F500)-'Jun 2026'!T5 | C29: ='Jun 2026'!L18-'Jun 2026'!L19 | D29: =B29-C29 | E29: =IF(B29=0,0,D29/B29) | F29: ='Jun 2026'!L17 | G29: =D29-F29
A30: Julho | B30: =SUMIF('Jul 2026'!A5:A500,"<>",'Jul 2026'!D5:D500)-SUMIF('Jul 2026'!A5:A500,"<>",'Jul 2026'!F5:F500)-'Jul 2026'!T5 | C30: ='Jul 2026'!L18-'Jul 2026'!L19 | D30: =B30-C30 | E30: =IF(B30=0,0,D30/B30) | F30: ='Jul 2026'!L17 | G30: =D30-F30
A31: Agosto | B31: =SUMIF('Ago 2026'!E5:E500,"<>",'Ago 2026'!D5:D500)-SUMIF('Ago 2026'!E5:E500,"<>",'Ago 2026'!F5:F500)-SUMIF('Ago 2026'!E5:E500,"Aguardando Pagamento",'Ago 2026'!D5:D500) | C31: ='Ago 2026'!L18-'Ago 2026'!L19 | D31: =B31-C31 | E31: =IF(B31=0,0,D31/B31) | F31: ='Ago 2026'!L17 | G31: =D31-F31
A32: Setembro | B32: =SUMIF('Set 2026'!E5:E500,"<>",'Set 2026'!D5:D500)-SUMIF('Set 2026'!E5:E500,"<>",'Set 2026'!F5:F500)-SUMIF('Set 2026'!E5:E500,"Aguardando Pagamento",'Set 2026'!D5:D500) | C32: ='Set 2026'!L18-'Set 2026'!L19 | D32: =B32-C32 | E32: =IF(B32=0,0,D32/B32) | F32: ='Set 2026'!L17 | G32: =D32-F32
A33: Outubro | B33: =SUMIF('Out 2026'!E5:E500,"<>",'Out 2026'!D5:D500)-SUMIF('Out 2026'!E5:E500,"<>",'Out 2026'!F5:F500)-SUMIF('Out 2026'!E5:E500,"Aguardando Pagamento",'Out 2026'!D5:D500) | C33: ='Out 2026'!L18-'Out 2026'!L19 | D33: =B33-C33 | E33: =IF(B33=0,0,D33/B33) | F33: ='Out 2026'!L17 | G33: =D33-F33
A34: Novembro | B34: =SUMIF('Nov 2026'!E5:E500,"<>",'Nov 2026'!D5:D500)-SUMIF('Nov 2026'!E5:E500,"<>",'Nov 2026'!F5:F500)-SUMIF('Nov 2026'!E5:E500,"Aguardando Pagamento",'Nov 2026'!D5:D500) | C34: ='Nov 2026'!L18-'Nov 2026'!L19 | D34: =B34-C34 | E34: =IF(B34=0,0,D34/B34) | F34: ='Nov 2026'!L17 | G34: =D34-F34
A35: Dezembro | B35: =SUMIF('Dez 2026'!E5:E500,"<>",'Dez 2026'!D5:D500)-SUMIF('Dez 2026'!E5:E500,"<>",'Dez 2026'!F5:F500)-SUMIF('Dez 2026'!E5:E500,"Aguardando Pagamento",'Dez 2026'!D5:D500) | C35: ='Dez 2026'!L18-'Dez 2026'!L19 | D35: =B35-C35 | E35: =IF(B35=0,0,D35/B35) | F35: ='Dez 2026'!L17 | G35: =D35-F35
A36: TOTAL / MÉDIA | B36: =SUM(B24:B35) | C36: =SUM(C24:C35) | D36: =SUM(D24:D35) | E36: =IF(B36=0,0,D36/B36) | F36: =SUM(F24:F35) | G36: =SUM(G24:G35)
A39: Saídas por Categoria (Ano 2026) | F39: Contas a Receber — Vendas Pendentes (Ago–Dez/2026)
A40: Categoria | B40: Valor (R$) | C40: % do Total | F40: Mês | H40: Valor (R$)
A41: Fornecedores / Mercadoria | B41: =SUMIF('Jan 2026'!H5:H500,$A41,'Jan 2026'!G5:G500)+SUMIF('Fev 2026'!H5:H500,$A41,'Fev 2026'!G5:G500)+SUMIF('Mar 2026'!H5:H500,$A41,'Mar 2026'!G5:G500)+SUMIF('Abr 2026'!H5:H500,$A41,'Abr 2026'!G5:G500)+SUMIF('Mai 2026'!H5:H500,$A41,'Mai 2026'!G5:G500)+SUMIF('Jun 2026'!H5:H500,$A41,'Jun 2026'!G5:G500)+SUMIF('Jul 2026'!H5:H500,$A41,'Jul 2026'!G5:G500)+SUMIF('Ago 2026'!H5:H500,$A41,'Ago 2026'!G5:G500)+SUMIF('Set 2026'!H5:H500,$A41,'Set 2026'!G5:G500)+SUMIF('Out 2026'!H5:H500,$A41,'Out 2026'!G5:G500)+SUMIF('Nov 2026'!H5:H500,$A41,'Nov 2026'!G5:G500)+SUMIF('Dez 2026'!H5:H500,$A41,'Dez 2026'!G5:G500) | C41: =IF($B$54=0,0,B41/$B$54) | F41: Agosto | H41: =SUMIF('Ago 2026'!E5:E500,"Aguardando Pagamento",'Ago 2026'!D5:D500)
A42: Aluguel | B42: =SUMIF('Jan 2026'!H5:H500,$A42,'Jan 2026'!G5:G500)+SUMIF('Fev 2026'!H5:H500,$A42,'Fev 2026'!G5:G500)+SUMIF('Mar 2026'!H5:H500,$A42,'Mar 2026'!G5:G500)+SUMIF('Abr 2026'!H5:H500,$A42,'Abr 2026'!G5:G500)+SUMIF('Mai 2026'!H5:H500,$A42,'Mai 2026'!G5:G500)+SUMIF('Jun 2026'!H5:H500,$A42,'Jun 2026'!G5:G500)+SUMIF('Jul 2026'!H5:H500,$A42,'Jul 2026'!G5:G500)+SUMIF('Ago 2026'!H5:H500,$A42,'Ago 2026'!G5:G500)+SUMIF('Set 2026'!H5:H500,$A42,'Set 2026'!G5:G500)+SUMIF('Out 2026'!H5:H500,$A42,'Out 2026'!G5:G500)+SUMIF('Nov 2026'!H5:H500,$A42,'Nov 2026'!G5:G500)+SUMIF('Dez 2026'!H5:H500,$A42,'Dez 2026'!G5:G500) | C42: =IF($B$54=0,0,B42/$B$54) | F42: Setembro | H42: =SUMIF('Set 2026'!E5:E500,"Aguardando Pagamento",'Set 2026'!D5:D500)
A43: Água, Energia e Internet | B43: =SUMIF('Jan 2026'!H5:H500,$A43,'Jan 2026'!G5:G500)+SUMIF('Fev 2026'!H5:H500,$A43,'Fev 2026'!G5:G500)+SUMIF('Mar 2026'!H5:H500,$A43,'Mar 2026'!G5:G500)+SUMIF('Abr 2026'!H5:H500,$A43,'Abr 2026'!G5:G500)+SUMIF('Mai 2026'!H5:H500,$A43,'Mai 2026'!G5:G500)+SUMIF('Jun 2026'!H5:H500,$A43,'Jun 2026'!G5:G500)+SUMIF('Jul 2026'!H5:H500,$A43,'Jul 2026'!G5:G500)+SUMIF('Ago 2026'!H5:H500,$A43,'Ago 2026'!G5:G500)+SUMIF('Set 2026'!H5:H500,$A43,'Set 2026'!G5:G500)+SUMIF('Out 2026'!H5:H500,$A43,'Out 2026'!G5:G500)+SUMIF('Nov 2026'!H5:H500,$A43,'Nov 2026'!G5:G500)+SUMIF('Dez 2026'!H5:H500,$A43,'Dez 2026'!G5:G500) | C43: =IF($B$54=0,0,B43/$B$54) | F43: Outubro | H43: =SUMIF('Out 2026'!E5:E500,"Aguardando Pagamento",'Out 2026'!D5:D500)
A44: Impostos e Taxas | B44: =SUMIF('Jan 2026'!H5:H500,$A44,'Jan 2026'!G5:G500)+SUMIF('Fev 2026'!H5:H500,$A44,'Fev 2026'!G5:G500)+SUMIF('Mar 2026'!H5:H500,$A44,'Mar 2026'!G5:G500)+SUMIF('Abr 2026'!H5:H500,$A44,'Abr 2026'!G5:G500)+SUMIF('Mai 2026'!H5:H500,$A44,'Mai 2026'!G5:G500)+SUMIF('Jun 2026'!H5:H500,$A44,'Jun 2026'!G5:G500)+SUMIF('Jul 2026'!H5:H500,$A44,'Jul 2026'!G5:G500)+SUMIF('Ago 2026'!H5:H500,$A44,'Ago 2026'!G5:G500)+SUMIF('Set 2026'!H5:H500,$A44,'Set 2026'!G5:G500)+SUMIF('Out 2026'!H5:H500,$A44,'Out 2026'!G5:G500)+SUMIF('Nov 2026'!H5:H500,$A44,'Nov 2026'!G5:G500)+SUMIF('Dez 2026'!H5:H500,$A44,'Dez 2026'!G5:G500) | C44: =IF($B$54=0,0,B44/$B$54) | F44: Novembro | H44: =SUMIF('Nov 2026'!E5:E500,"Aguardando Pagamento",'Nov 2026'!D5:D500)
A45: Tarifas Bancárias e Cartão | B45: =SUMIF('Jan 2026'!H5:H500,$A45,'Jan 2026'!G5:G500)+SUMIF('Fev 2026'!H5:H500,$A45,'Fev 2026'!G5:G500)+SUMIF('Mar 2026'!H5:H500,$A45,'Mar 2026'!G5:G500)+SUMIF('Abr 2026'!H5:H500,$A45,'Abr 2026'!G5:G500)+SUMIF('Mai 2026'!H5:H500,$A45,'Mai 2026'!G5:G500)+SUMIF('Jun 2026'!H5:H500,$A45,'Jun 2026'!G5:G500)+SUMIF('Jul 2026'!H5:H500,$A45,'Jul 2026'!G5:G500)+SUMIF('Ago 2026'!H5:H500,$A45,'Ago 2026'!G5:G500)+SUMIF('Set 2026'!H5:H500,$A45,'Set 2026'!G5:G500)+SUMIF('Out 2026'!H5:H500,$A45,'Out 2026'!G5:G500)+SUMIF('Nov 2026'!H5:H500,$A45,'Nov 2026'!G5:G500)+SUMIF('Dez 2026'!H5:H500,$A45,'Dez 2026'!G5:G500) | C45: =IF($B$54=0,0,B45/$B$54) | F45: Dezembro | H45: =SUMIF('Dez 2026'!E5:E500,"Aguardando Pagamento",'Dez 2026'!D5:D500)
A46: Transporte e Entregas | B46: =SUMIF('Jan 2026'!H5:H500,$A46,'Jan 2026'!G5:G500)+SUMIF('Fev 2026'!H5:H500,$A46,'Fev 2026'!G5:G500)+SUMIF('Mar 2026'!H5:H500,$A46,'Mar 2026'!G5:G500)+SUMIF('Abr 2026'!H5:H500,$A46,'Abr 2026'!G5:G500)+SUMIF('Mai 2026'!H5:H500,$A46,'Mai 2026'!G5:G500)+SUMIF('Jun 2026'!H5:H500,$A46,'Jun 2026'!G5:G500)+SUMIF('Jul 2026'!H5:H500,$A46,'Jul 2026'!G5:G500)+SUMIF('Ago 2026'!H5:H500,$A46,'Ago 2026'!G5:G500)+SUMIF('Set 2026'!H5:H500,$A46,'Set 2026'!G5:G500)+SUMIF('Out 2026'!H5:H500,$A46,'Out 2026'!G5:G500)+SUMIF('Nov 2026'!H5:H500,$A46,'Nov 2026'!G5:G500)+SUMIF('Dez 2026'!H5:H500,$A46,'Dez 2026'!G5:G500) | C46: =IF($B$54=0,0,B46/$B$54) | F46: Total a Receber | H46: =SUM(H41:H45)
A47: Salários, Comissões e Encargos | B47: =SUMIF('Jan 2026'!H5:H500,$A47,'Jan 2026'!G5:G500)+SUMIF('Fev 2026'!H5:H500,$A47,'Fev 2026'!G5:G500)+SUMIF('Mar 2026'!H5:H500,$A47,'Mar 2026'!G5:G500)+SUMIF('Abr 2026'!H5:H500,$A47,'Abr 2026'!G5:G500)+SUMIF('Mai 2026'!H5:H500,$A47,'Mai 2026'!G5:G500)+SUMIF('Jun 2026'!H5:H500,$A47,'Jun 2026'!G5:G500)+SUMIF('Jul 2026'!H5:H500,$A47,'Jul 2026'!G5:G500)+SUMIF('Ago 2026'!H5:H500,$A47,'Ago 2026'!G5:G500)+SUMIF('Set 2026'!H5:H500,$A47,'Set 2026'!G5:G500)+SUMIF('Out 2026'!H5:H500,$A47,'Out 2026'!G5:G500)+SUMIF('Nov 2026'!H5:H500,$A47,'Nov 2026'!G5:G500)+SUMIF('Dez 2026'!H5:H500,$A47,'Dez 2026'!G5:G500) | C47: =IF($B$54=0,0,B47/$B$54)
...

Sheet DRE Simplificado
A1: DRE SIMPLIFICADO — 2026
A2: Receita − Custos Variáveis = Margem de Contribuição. Margem − Custos Fixos = Resultado da loja. Resultado da loja − Pró-labore da Edilânia = SOBRA FINAL. Puxa tudo das abas mensais, sem digitação.
A3: ← Início | B3: =SUM(B38:M38) | C3: ← meses já fechados (o mês em andamento fica fora); é a base da coluna "Média/mês"
A4: Conta | B4: Janeiro | C4: Fevereiro | D4: Março | E4: Abril | F4: Maio | G4: Junho | H4: Julho | I4: Agosto | J4: Setembro | K4: Outubro | L4: Novembro | M4: Dezembro | N4: Total | O4: Média/mês
A5: RECEITA LÍQUIDA (vendas recebidas) | B5: =SUMIF('Jan 2026'!A5:A500,"<>",'Jan 2026'!D5:D500)-SUMIF('Jan 2026'!A5:A500,"<>",'Jan 2026'!F5:F500)-'Jan 2026'!T5 | C5: =SUMIF('Fev 2026'!A5:A500,"<>",'Fev 2026'!D5:D500)-SUMIF('Fev 2026'!A5:A500,"<>",'Fev 2026'!F5:F500)-'Fev 2026'!T5 | D5: =SUMIF('Mar 2026'!A5:A500,"<>",'Mar 2026'!D5:D500)-SUMIF('Mar 2026'!A5:A500,"<>",'Mar 2026'!F5:F500)-'Mar 2026'!T5 | E5: =SUMIF('Abr 2026'!A5:A500,"<>",'Abr 2026'!D5:D500)-SUMIF('Abr 2026'!A5:A500,"<>",'Abr 2026'!F5:F500)-'Abr 2026'!T5 | F5: =SUMIF('Mai 2026'!A5:A500,"<>",'Mai 2026'!D5:D500)-SUMIF('Mai 2026'!A5:A500,"<>",'Mai 2026'!F5:F500)-'Mai 2026'!T5 | G5: =SUMIF('Jun 2026'!A5:A500,"<>",'Jun 2026'!D5:D500)-SUMIF('Jun 2026'!A5:A500,"<>",'Jun 2026'!F5:F500)-'Jun 2026'!T5 | H5: =SUMIF('Jul 2026'!A5:A500,"<>",'Jul 2026'!D5:D500)-SUMIF('Jul 2026'!A5:A500,"<>",'Jul 2026'!F5:F500)-'Jul 2026'!T5 | I5: =SUMIF('Ago 2026'!E5:E500,"<>",'Ago 2026'!D5:D500)-SUMIF('Ago 2026'!E5:E500,"<>",'Ago 2026'!F5:F500)-'Ago 2026'!T5 | J5: =SUMIF('Set 2026'!E5:E500,"<>",'Set 2026'!D5:D500)-SUMIF('Set 2026'!E5:E500,"<>",'Set 2026'!F5:F500)-'Set 2026'!T5 | K5: =SUMIF('Out 2026'!E5:E500,"<>",'Out 2026'!D5:D500)-SUMIF('Out 2026'!E5:E500,"<>",'Out 2026'!F5:F500)-'Out 2026'!T5 | L5: =SUMIF('Nov 2026'!E5:E500,"<>",'Nov 2026'!D5:D500)-SUMIF('Nov 2026'!E5:E500,"<>",'Nov 2026'!F5:F500)-'Nov 2026'!T5 | M5: =SUMIF('Dez 2026'!E5:E500,"<>",'Dez 2026'!D5:D500)-SUMIF('Dez 2026'!E5:E500,"<>",'Dez 2026'!F5:F500)-'Dez 2026'!T5 | N5: =SUM(B5:M5) | O5: =IF($B$3=0,0,SUMPRODUCT(B5:M5,$B$38:$M$38)/$B$3)
A6: (−) Fornecedores / Mercadoria | B6: ='Jan 2026'!L5 | C6: ='Fev 2026'!L5 | D6: ='Mar 2026'!L5 | E6: ='Abr 2026'!L5 | F6: ='Mai 2026'!L5 | G6: ='Jun 2026'!L5 | H6: ='Jul 2026'!L5 | I6: ='Ago 2026'!L5 | J6: ='Set 2026'!L5 | K6: ='Out 2026'!L5 | L6: ='Nov 2026'!L5 | M6: ='Dez 2026'!L5 | N6: =SUM(B6:M6) | O6: =IF($B$3=0,0,SUMPRODUCT(B6:M6,$B$38:$M$38)/$B$3)
A7: (−) Impostos e Taxas | B7: ='Jan 2026'!L8 | C7: ='Fev 2026'!L8 | D7: ='Mar 2026'!L8 | E7: ='Abr 2026'!L8 | F7: ='Mai 2026'!L8 | G7: ='Jun 2026'!L8 | H7: ='Jul 2026'!L8 | I7: ='Ago 2026'!L8 | J7: ='Set 2026'!L8 | K7: ='Out 2026'!L8 | L7: ='Nov 2026'!L8 | M7: ='Dez 2026'!L8 | N7: =SUM(B7:M7) | O7: =IF($B$3=0,0,SUMPRODUCT(B7:M7,$B$38:$M$38)/$B$3)
A8: (−) Transporte e Entregas (frete, gasolina, moto táxi) | B8: ='Jan 2026'!L10-B21 | C8: ='Fev 2026'!L10-C21 | D8: ='Mar 2026'!L10-D21 | E8: ='Abr 2026'!L10-E21 | F8: ='Mai 2026'!L10-F21 | G8: ='Jun 2026'!L10-G21 | H8: ='Jul 2026'!L10-H21 | I8: ='Ago 2026'!L10-I21 | J8: ='Set 2026'!L10-J21 | K8: ='Out 2026'!L10-K21 | L8: ='Nov 2026'!L10-L21 | M8: ='Dez 2026'!L10-M21 | N8: =SUM(B8:M8) | O8: =IF($B$3=0,0,SUMPRODUCT(B8:M8,$B$38:$M$38)/$B$3)
A9: (−) Comissões (Wiliam — por troca/instalação) | B9: =SUMIFS('Jan 2026'!G5:G500,'Jan 2026'!B5:B500,"Comissão*",'Jan 2026'!H5:H500,"Salários, Comissões e Encargos") | C9: =SUMIFS('Fev 2026'!G5:G500,'Fev 2026'!B5:B500,"Comissão*",'Fev 2026'!H5:H500,"Salários, Comissões e Encargos") | D9: =SUMIFS('Mar 2026'!G5:G500,'Mar 2026'!B5:B500,"Comissão*",'Mar 2026'!H5:H500,"Salários, Comissões e Encargos") | E9: =SUMIFS('Abr 2026'!G5:G500,'Abr 2026'!B5:B500,"Comissão*",'Abr 2026'!H5:H500,"Salários, Comissões e Encargos") | F9: =SUMIFS('Mai 2026'!G5:G500,'Mai 2026'!B5:B500,"Comissão*",'Mai 2026'!H5:H500,"Salários, Comissões e Encargos") | G9: =SUMIFS('Jun 2026'!G5:G500,'Jun 2026'!B5:B500,"Comissão*",'Jun 2026'!H5:H500,"Salários, Comissões e Encargos") | H9: =SUMIFS('Jul 2026'!G5:G500,'Jul 2026'!B5:B500,"Comissão*",'Jul 2026'!H5:H500,"Salários, Comissões e Encargos") | I9: =SUMIFS('Ago 2026'!G5:G500,'Ago 2026'!B5:B500,"Comissão*",'Ago 2026'!H5:H500,"Salários, Comissões e Encargos") | J9: =SUMIFS('Set 2026'!G5:G500,'Set 2026'!B5:B500,"Comissão*",'Set 2026'!H5:H500,"Salários, Comissões e Encargos") | K9: =SUMIFS('Out 2026'!G5:G500,'Out 2026'!B5:B500,"Comissão*",'Out 2026'!H5:H500,"Salários, Comissões e Encargos") | L9: =SUMIFS('Nov 2026'!G5:G500,'Nov 2026'!B5:B500,"Comissão*",'Nov 2026'!H5:H500,"Salários, Comissões e Encargos") | M9: =SUMIFS('Dez 2026'!G5:G500,'Dez 2026'!B5:B500,"Comissão*",'Dez 2026'!H5:H500,"Salários, Comissões e Encargos") | N9: =SUM(B9:M9) | O9: =IF($B$3=0,0,SUMPRODUCT(B9:M9,$B$38:$M$38)/$B$3)
A10: (=) CUSTOS VARIÁVEIS | B10: =SUM(B6:B9) | C10: =SUM(C6:C9) | D10: =SUM(D6:D9) | E10: =SUM(E6:E9) | F10: =SUM(F6:F9) | G10: =SUM(G6:G9) | H10: =SUM(H6:H9) | I10: =SUM(I6:I9) | ... M10: =SUM(M6:M9) | N10: =SUM(B10:M10) | O10: =IF($B$3=0,0,SUMPRODUCT(B10:M10,$B$38:$M$38)/$B$3)
A11: (=) MARGEM DE CONTRIBUIÇÃO | B11: =B5-B10 | C11: =C5-C10 | D11: =D5-D10 | E11: =E5-E10 | F11: =F5-F10 | G11: =G5-G10 | H11: =H5-H10 | I11: =I5-I10 | ... M11: =M5-M10 | N11: =SUM(B11:M11) | O11: =IF($B$3=0,0,SUMPRODUCT(B11:M11,$B$38:$M$38)/$B$3)
A12: Margem de Contribuição (%) | B12: =IF(B5=0,"",B11/B5) | C12: =IF(C5=0,"",C11/C5) | D12: =IF(D5=0,"",D11/D5) | E12: =IF(E5=0,"",E11/E5) | F12: =IF(F5=0,"",F11/F5) | G12: =IF(G5=0,"",G11/G5) | H12: =IF(H5=0,"",H11/H5) | I12: =IF(I5=0,"",I11/I5) | ... O12: =IF(O5=0,"",O11/O5)
A13: (−) Aluguel | B13: ='Jan 2026'!L6 | C13: ='Fev 2026'!L6 | D13: ='Mar 2026'!L6 | E13: ='Abr 2026'!L6 | F13: ='Mai 2026'!L6 | G13: ='Jun 2026'!L6 | H13: ='Jul 2026'!L6 | I13: ='Ago 2026'!L6 | J13: ='Set 2026'!L6 | K13: ='Out 2026'!L6 | L13: ='Nov 2026'!L6 | M13: ='Dez 2026'!L6 | N13: =SUM(B13:M13) | O13: =IF($B$3=0,0,SUMPRODUCT(B13:M13,$B$38:$M$38)/$B$3)
A14: (−) Água, Energia e Internet | B14: ='Jan 2026'!L7 | C14: ='Fev 2026'!L7 | D14: ='Mar 2026'!L7 | E14: ='Abr 2026'!L7 | F14: ='Mai 2026'!L7 | G14: ='Jun 2026'!L7 | H14: ='Jul 2026'!L7 | I14: ='Ago 2026'!L7 | J14: ='Set 2026'!L7 | K14: ='Out 2026'!L7 | L14: ='Nov 2026'!L7 | M14: ='Dez 2026'!L7 | N14: =SUM(B14:M14) | O14: =IF($B$3=0,0,SUMPRODUCT(B14:M14,$B$38:$M$38)/$B$3)
A15: (−) Tarifas Bancárias e Cartão | B15: ='Jan 2026'!L9 | C15: ='Fev 2026'!L9 | D15: ='Mar 2026'!L9 | E15: ='Abr 2026'!L9 | F15: ='Mai 2026'!L9 | G15: ='Jun 2026'!L9 | H15: ='Jul 2026'!L9 | I15: ='Ago 2026'!L9 | J15: ='Set 2026'!L9 | K15: ='Out 2026'!L9 | L15: ='Nov 2026'!L9 | M15: ='Dez 2026'!L9 | N15: =SUM(B15:M15) | O15: =IF($B$3=0,0,SUMPRODUCT(B15:M15,$B$38:$M$38)/$B$3)
A16: (−) Salários e Encargos (sem as comissões) | B16: ='Jan 2026'!L11-B9 | C16: ='Fev 2026'!L11-C9 | D16: ='Mar 2026'!L11-D9 | E16: ='Abr 2026'!L11-E9 | F16: ='Mai 2026'!L11-F9 | G16: ='Jun 2026'!L11-G9 | H16: ='Jul 2026'!L11-H9 | I16: ='Ago 2026'!L11-I9 | J16: ='Set 2026'!L11-J9 | K16: ='Out 2026'!L11-K9 | L16: ='Nov 2026'!L11-L9 | M16: ='Dez 2026'!L11-M9 | N16: =SUM(B16:M16) | O16: =IF($B$3=0,0,SUMPRODUCT(B16:M16,$B$38:$M$38)/$B$3)
A17: (−) Contabilidade | B17: ='Jan 2026'!L12 | C17: ='Fev 2026'!L12 | D17: ='Mar 2026'!L12 | E17: ='Abr 2026'!L12 | F17: ='Mai 2026'!L12 | G17: ='Jun 2026'!L12 | H17: ='Jul 2026'!L12 | I17: ='Ago 2026'!L12 | J17: ='Set 2026'!L12 | K17: ='Out 2026'!L12 | L17: ='Nov 2026'!L12 | M17: ='Dez 2026'!L12 | N17: =SUM(B17:M17) | O17: =IF($B$3=0,0,SUMPRODUCT(B17:M17,$B$38:$M$38)/$B$3)
A18: (−) Manutenção e Reparos | B18: ='Jan 2026'!L13 | C18: ='Fev 2026'!L13 | D18: ='Mar 2026'!L13 | E18: ='Abr 2026'!L13 | F18: ='Mai 2026'!L13 | G18: ='Jun 2026'!L13 | H18: ='Jul 2026'!L13 | I18: ='Ago 2026'!L13 | J18: ='Set 2026'!L13 | K18: ='Out 2026'!L13 | L18: ='Nov 2026'!L13 | M18: ='Dez 2026'!L13 | N18: =SUM(B18:M18) | O18: =IF($B$3=0,0,SUMPRODUCT(B18:M18,$B$38:$M$38)/$B$3)
A19: (−) Material de Limpeza e Escritório | B19: ='Jan 2026'!L14 | C19: ='Fev 2026'!L14 | D19: ='Mar 2026'!L14 | E19: ='Abr 2026'!L14 | F19: ='Mai 2026'!L14 | G19: ='Jun 2026'!L14 | H19: ='Jul 2026'!L14 | I19: ='Ago 2026'!L14 | J19: ='Set 2026'!L14 | K19: ='Out 2026'!L14 | L19: ='Nov 2026'!L14 | M19: ='Dez 2026'!L14 | N19: =SUM(B19:M19) | O19: =IF($B$3=0,0,SUMPRODUCT(B19:M19,$B$38:$M$38)/$B$3)
A20: (−) Estornos de Vendas (Cancelamentos) | B20: ='Jan 2026'!L15 | C20: ='Fev 2026'!L15 | D20: ='Mar 2026'!L15 | E20: ='Abr 2026'!L15 | F20: ='Mai 2026'!L15 | G20: ='Jun 2026'!L15 | H20: ='Jul 2026'!L15 | I20: ='Ago 2026'!L15 | J20: ='Set 2026'!L15 | K20: ='Out 2026'!L15 | L20: ='Nov 2026'!L15 | M20: ='Dez 2026'!L15 | N20: =SUM(B20:M20) | O20: =IF($B$3=0,0,SUMPRODUCT(B20:M20,$B$38:$M$38)/$B$3)
A21: (−) Estacionamento (dentro de Transporte e Entregas) | B21: =SUMIF('Jan 2026'!B5:B500,"Estacionamento*",'Jan 2026'!G5:G500) | C21: =SUMIF('Fev 2026'!B5:B500,"Estacionamento*",'Fev 2026'!G5:G500) | D21: =SUMIF('Mar 2026'!B5:B500,"Estacionamento*",'Mar 2026'!G5:G500) | E21: =SUMIF('Abr 2026'!B5:B500,"Estacionamento*",'Abr 2026'!G5:G500) | F21: =SUMIF('Mai 2026'!B5:B500,"Estacionamento*",'Mai 2026'!G5:G500) | G21: =SUMIF('Jun 2026'!B5:B500,"Estacionamento*",'Jun 2026'!G5:G500) | H21: =SUMIF('Jul 2026'!B5:B500,"Estacionamento*",'Jul 2026'!G5:G500) | I21: =SUMIF('Ago 2026'!B5:B500,"Estacionamento*",'Ago 2026'!G5:G500) | J21: =SUMIF('Set 2026'!B5:B500,"Estacionamento*",'Set 2026'!G5:G500) | K21: =SUMIF('Out 2026'!B5:B500,"Estacionamento*",'Out 2026'!G5:G500) | L21: =SUMIF('Nov 2026'!B5:B500,"Estacionamento*",'Nov 2026'!G5:G500) | M21: =SUMIF('Dez 2026'!B5:B500,"Estacionamento*",'Dez 2026'!G5:G500) | N21: =SUM(B21:M21) | O21: =IF($B$3=0,0,SUMPRODUCT(B21:M21,$B$38:$M$38)/$B$3)
A22: (−) Outras Despesas | B22: ='Jan 2026'!L16 | C22: ='Fev 2026'!L16 | D22: ='Mar 2026'!L16 | E22: ='Abr 2026'!L16 | F22: ='Mai 2026'!L16 | G22: ='Jun 2026'!L16 | H22: ='Jul 2026'!L16 | I22: ='Ago 2026'!L16 | J22: ='Set 2026'!L16 | K22: ='Out 2026'!L16 | L22: ='Nov 2026'!L16 | M22: ='Dez 2026'!L16 | N22: =SUM(B22:M22) | O22: =IF($B$3=0,0,SUMPRODUCT(B22:M22,$B$38:$M$38)/$B$3)
A23: (=) CUSTOS FIXOS | B23: =SUM(B13:B22) | C23: =SUM(C13:C22) | D23: =SUM(D13:D22) | E23: =SUM(E13:E22) | F23: =SUM(F13:F22) | G23: =SUM(G13:G22) | H23: =SUM(H13:H22) | I23: =SUM(I13:I22) | ... M23: =SUM(M13:M22) | N23: =SUM(B23:M23) | O23: =IF($B$3=0,0,SUMPRODUCT(B23:M23,$B$38:$M$38)/$B$3)
A24: (=) RESULTADO DA LOJA (antes do pró-labore) | B24: =B11-B23 | C24: =C11-C23 | D24: =D11-D23 | E24: =E11-E23 | F24: =F11-F23 | G24: =G11-G23 | H24: =H11-H23 | I24: =I11-I23 | ... M24: =M11-M23 | N24: =SUM(B24:M24) | O24: =IF($B$3=0,0,SUMPRODUCT(B24:M24,$B$38:$M$38)/$B$3)
A25: Margem Líquida (%) | B25: =IF(B5=0,"",B24/B5) | C25: =IF(C5=0,"",C24/C5) | D25: =IF(D5=0,"",D24/D5) | E25: =IF(E5=0,"",E24/E5) | F25: =IF(F5=0,"",F24/F5) | G25: =IF(G5=0,"",G24/G5) | H25: =IF(H5=0,"",H24/H5) | I25: =IF(I5=0,"",I24/I5) | ... O25: =IF(O5=0,"",O24/O5)
A26: (−) Pró-labore Edilânia (tudo o que ela gastou do dinheiro da loja) | B26: ='Jan 2026'!L17 | C26: ='Fev 2026'!L17 | D26: ='Mar 2026'!L17 | E26: ='Abr 2026'!L17 | F26: ='Mai 2026'!L17 | G26: ='Jun 2026'!L17 | H26: ='Jul 2026'!L17 | I26: ='Ago 2026'!L17 | J26: ='Set 2026'!L17 | K26: ='Out 2026'!L17 | L26: ='Nov 2026'!L17 | M26: ='Dez 2026'!L17 | N26: =SUM(B26:M26) | O26: =IF($B$3=0,0,SUMPRODUCT(B26:M26,$B$38:$M$38)/$B$3)
A27: (=) SOBRA FINAL (depois do pró-labore) | B27: =B24-B26 | C27: =C24-C26 | D27: =D24-D26 | E27: =E24-E26 | F27: =F24-F26 | G27: =G24-G26 | H27: =H24-H26 | I27: =I24-I26 | ... M27: =M24-M26 | N27: =SUM(B27:M27) | O27: =IF($B$3=0,0,SUMPRODUCT(B27:M27,$B$38:$M$38)/$B$3)
A28: Combinado com ela: sobrou (+) ou passou (−) do combinado | B28: =IF(B5=0,"",'Ponto de Equilíbrio'!$B$10-B26) | C28: =IF(C5=0,"",'Ponto de Equilíbrio'!$B$10-C26) | D28: =IF(D5=0,"",'Ponto de Equilíbrio'!$B$10-D26) | E28: =IF(E5=0,"",'Ponto de Equilíbrio'!$B$10-E26) | F28: =IF(F5=0,"",'Ponto de Equilíbrio'!$B$10-F26) | G28: =IF(G5=0,"",'Ponto de Equilíbrio'!$B$10-G26) | H28: =IF(H5=0,"",'Ponto de Equilíbrio'!$B$10-H26) | I28: =IF(I5=0,"",'Ponto de Equilíbrio'!$B$10-I26) | ... M28: =IF(M5=0,"",'Ponto de Equilíbrio'!$B$10-M26) | N28: =SUM(B28:M28) | O28: =IF($B$3=0,0,SUMPRODUCT(B28:M28,$B$38:$M$38)/$B$3)
A30: MEMÓRIA (não entra no resultado)
A31: Despesas da loja pagas com Capital de Giro (BB) — dívida a devolver | B31: ='Jan 2026'!L19 | C31: ='Fev 2026'!L19 | D31: ='Mar 2026'!L19 | E31: ='Abr 2026'!L19 | F31: ='Mai 2026'!L19 | G31: ='Jun 2026'!L19 | H31: ='Jul 2026'!L19 | I31: ='Ago 2026'!L19 | J31: ='Set 2026'!L19 | K31: ='Out 2026'!L19 | L31: ='Nov 2026'!L19 | M31: ='Dez 2026'!L19 | N31: =SUM(B31:M31) | O31: =IF($B$3=0,0,SUMPRODUCT(B31:M31,$B$38:$M$38)/$B$3)
A33: Custos Variáveis = sobem/descem com o volume vendido: mercadoria, imposto sobre faturamento (DAS), transporte ligado ao serviço e as comissões do Wiliam (só existem quando tem troca/instalação). Custos Fixos = o que a loja paga mesmo vendendo pouco (aluguel, energia, salários, contabilidade, tarifas e o estacionamento, contratado no mês).
A34: A Receita de Ago–Dez já está líquida: descontadas as taxas de máquina e as vendas ainda não recebidas (A Receber).
A35: A "Média/mês" divide só pelos meses JÁ FECHADOS (linha 38 = 1). O mês em andamento fica fora da média até terminar, para um mês pela metade não puxar o número para baixo.
A36: ATENÇÃO — este DRE é por COMPETÊNCIA: considera a despesa no mês em que ela aconteceu, mesmo que tenha sido paga pelo Capital de Giro do BB. Por isso o Resultado aqui é menor que o cartão SALDO da aba do mês e que o Lucro do Dashboard, que são CAIXA puro. A diferença está na linha 28.
A37: PRÓ-LABORE: tudo o que a Edilânia gasta do dinheiro da loja (contas da casa, Pix pessoais, mercado, diarista...) é o pró-labore dela. O combinado é o valor da célula B10 da aba "Ponto de Equilíbrio" (R$ 4.000,00/mês desde 05/10/2026). A linha 28 mostra, mês a mês, se sobrou ou se passou do combinado.
A38: Entra na média? (1 = mês já fechado e com movimento) | B38: =IF(AND(B5>0,1<IF(YEAR(TODAY())>2026,13,MONTH(TODAY()))),1,0) | C38: =IF(AND(C5>0,2<IF(YEAR(TODAY())>2026,13,MONTH(TODAY()))),1,0) | D38: =IF(AND(D5>0,3<IF(YEAR(TODAY())>2026,13,MONTH(TODAY()))),1,0) | E38: =IF(AND(E5>0,4<IF(YEAR(TODAY())>2026,13,MONTH(TODAY()))),1,0) | F38: =IF(AND(F5>0,5<IF(YEAR(TODAY())>2026,13,MONTH(TODAY()))),1,0) | G38: =IF(AND(G5>0,6<IF(YEAR(TODAY())>2026,13,MONTH(TODAY()))),1,0) | H38: =IF(AND(H5>0,7<IF(YEAR(TODAY())>2026,13,MONTH(TODAY()))),1,0) | I38: =IF(AND(I5>0,8<IF(YEAR(TODAY())>2026,13,MONTH(TODAY()))),1,0) | J38: =IF(AND(J5>0,9<IF(YEAR(TODAY())>2026,13,MONTH(TODAY()))),1,0) | K38: =IF(AND(K5>0,10<IF(YEAR(TODAY())>2026,13,MONTH(TODAY()))),1,0) | L38: =IF(AND(L5>0,11<IF(YEAR(TODAY())>2026,13,MONTH(TODAY()))),1,0) | M38: =IF(AND(M5>0,12<IF(YEAR(TODAY())>2026,13,MONTH(TODAY()))),1,0)

Sheet Contas a Pagar e Receber
A1: CONTAS A PAGAR E A RECEBER
A2: Compromissos em aberto e vendas ainda não recebidas. "Dias em Atraso" é calculado sozinho. O total a receber é puxado automaticamente das abas dos meses — não precisa somar à mão.
A3: ← Início
A4: TOTAL A PAGAR (EM ABERTO) | C4: TOTAL A RECEBER (AUTOMÁTICO) | E4: SALDO (RECEBER − PAGAR)
A5: =D97 | C5: ='Jan 2026'!T5+'Fev 2026'!T5+'Mar 2026'!T5+'Abr 2026'!T5+'Mai 2026'!T5+'Jun 2026'!T5+'Jul 2026'!T5+'Ago 2026'!T5+'Set 2026'!T5+'Out 2026'!T5+'Nov 2026'!T5+'Dez 2026'!T5 | E5: =C5-A5
A9: CONTAS A PAGAR — o que a loja ainda deve
A10: Fornecedor / Pessoa | B10: Descrição | C10: Vencimento | D10: Valor (R$) | E10: Status | F10: Dias em Atraso | G10: Observações
A11: Capital de Giro (BB) — saldo a devolver à reserva | B11: Dinheiro da reserva (Banco do Brasil) usado para pagar contas da loja | D11: ='Capital de Giro (BB)'!C5 | E11: Pendente | F11: =IF(OR($E11="Pago",$C11=""),"",MAX(0,TODAY()-$C11)) | G11: Detalhe na aba Capital de Giro (BB). Ago/2026 quitado em 31/08/2026. Em 30/09/2026 a reserva pagou R$ 3.272,00 à Knox (2 bebedouros industriais) — a devolver.
A12: Eversoft Ind e Com de Plasticos Ltda | B12: Mercadoria — doc. 72153 (emissão 02/04/2026) | C12: 46264 | D12: 878.93 | E12: Pago | F12: =IF(OR($E12="Pago",$C12=""),"",MAX(0,TODAY()-$C12)) | G12: Categoria: Fornecedores / Mercadoria. Pago em 31/08/2026 — lançado em "Ago 2026" como "Eversoft" (R$ 878,93).
A13: Empresa Baiana de Aguas e Saneamento SA (Embasa) | B13: Conta de água — despesa pessoal do dono (não é da loja) | C13: 46266 | D13: 50.08 | E13: Pago | F13: =IF(OR($E13="Pago",$C13=""),"",MAX(0,TODAY()-$C13)) | G13: Categoria: Pro Labore Edilânia. Pago em 01/09/2026 — lançado em Set 2026 como "Conta de Água Adriano".
A14: Vitoria Maria F Santos | B14: Aluguel da loja — setembro/2026 | C14: 46266 | D14: 880 | E14: Pago | F14: =IF(OR($E14="Pago",$C14=""),"",MAX(0,TODAY()-$C14)) | G14: Categoria: Aluguel. Pago em 01/09/2026 — lançado em Set 2026 como "Vitoria Maria F Santos".
A15: Wiliam Pinto Bispo | B15: Salário + comissões | C15: 46266 | D15: 1571.32 | E15: Pago | F15: =IF(OR($E15="Pago",$C15=""),"",MAX(0,TODAY()-$C15)) | G15: Categoria: Salários, Comissões e Encargos. Pago em 31/08/2026 (segunda-feira) — lançado em "Ago 2026" como "Salário Wiliam".
A16: Erick Feitosa Evangelista | B16: Salário do estagiário | C16: 46266 | D16: 600 | E16: Pago | F16: =IF(OR($E16="Pago",$C16=""),"",MAX(0,TODAY()-$C16)) | G16: Categoria: Salários, Comissões e Encargos. Pago em 31/08/2026 — lançado em "Ago 2026" como "Salário Erick (Estagiário)".
A17: Filtros Planeta Agua Ind e Com Ltda | B17: Mercadoria — doc. 131997 (emissão 08/07/2026) | C17: 46267 | D17: 1385.85 | E17: Pago | F17: =IF(OR($E17="Pago",$C17=""),"",MAX(0,TODAY()-$C17)) | G17: Categoria: Fornecedores / Mercadoria. Pago em 02/09/2026 — lançado em "Set 2026" como "Filtros Planeta Água".
A18: Everest Refrigeracao e Industria | B18: Mercadoria — doc. 374271 (emissão 06/04/2026) | C18: 46268 | D18: 706.67 | E18: Pago | F18: =IF(OR($E18="Pago",$C18=""),"",MAX(0,TODAY()-$C18)) | G18: Categoria: Fornecedores / Mercadoria. Pago em 03/09/2026 — lançado em "Set 2026" como "Everest Refrigeração".
A19: Eversoft Ind e Com de Plasticos Ltda | B19: Mercadoria — doc. 72869 (emissão 07/05/2026) | C19: 46269 | D19: 980.83 | E19: Pago | F19: =IF(OR($E19="Pago",$C19=""),"",MAX(0,TODAY()-$C19)) | G19: Categoria: Fornecedores / Mercadoria. Pago em 04/09/2026 pelo Banco do Nordeste (DOC 5301) — lançado em "Set 2026" como "Eversoft" (R$ 980,83).
A20: Neoenergia Coelba | B20: Energia elétrica da loja — REF 08/2026 (fatura em nome de Vitória Maria / Planeta Água) | C20: 46273 | D20: 150.06 | E20: Pago | F20: =IF(OR($E20="Pago",$C20=""),"",MAX(0,TODAY()-$C20)) | G20: Categoria: Água, Energia e Internet. Pago em 08/09/2026 — lançado em Set 2026 como "Conta de Energia Loja".
A21: Eversoft Ind e Com de Plasticos Ltda | B21: Mercadoria — doc. 73636 (emissão 10/06/2026) | C21: 46273 | D21: 878.92 | E21: Pago | F21: =IF(OR($E21="Pago",$C21=""),"",MAX(0,TODAY()-$C21)) | G21: Categoria: Fornecedores / Mercadoria. Pago em 08/09/2026 — lançado em Set 2026 como "Eversoft".
A22: Filtros Planeta Agua Ind e Com Ltda | B22: Mercadoria — doc. 133138/1 (emissão 12/08/2026) | C22: 46274 | D22: 649.83 | E22: Pago | F22: =IF(OR($E22="Pago",$C22=""),"",MAX(0,TODAY()-$C22)) | G22: Categoria: Fornecedores / Mercadoria. Boleto Itaú 341-7, nosso número 109/00257849-8. Pago em 09/09/2026 — lançado em "Set 2026" como "Filtros Planeta Água".
A23: Sindicato dos Empregados no Comércio de Jacobina | B23: Contribuição assistencial — competência junho/2026 | C23: 46275 | D23: 59.5 | E23: Pago | F23: =IF(OR($E23="Pago",$C23=""),"",MAX(0,TODAY()-$C23)) | G23: Categoria: Impostos e Taxas. Pago em 09/09/2026 (antecipado, venc. 10/09) — lançado em "Set 2026" como "Sindicato dos Empregados no Comércio de Jacobina".
... A94: Proxxima Telecomunicacoes S.A. | B94: Internet da loja — plano Turbinados 700 MB, contrato 578646 | C94: 46310 | D94: 69.99 | E94: Pago | F94: =IF(OR($E94="Pago",$C94=""),"",MAX(0,TODAY()-$C94)) | G94: Categoria quando pagar: Água, Energia e Internet. Fatura FAT26091809010676 (emissão 18/09/2026), NFCom 410732, boleto Bradesco 237. Linha digitável 23790.49303 90000.443094 56025.103005 3 16000000006999. Nosso número 09000044309567. Após o vencimento: multa de 2% + mora de 1,20% a.m. A fatura sai em nome do sócio, mas o serviço é da loja. Pago em 15/10/2026 — lançado em "Out 2026" como "Proxxima Telecomunicações".
A95: TOTAL A PAGAR — COM BOLETO EM MÃOS | D95: =SUMIF(E11:E94,"Pendente",D11:D94)
A96: PREVISTO — compromisso certo que ainda não está documentado | D96: =SUMIF(E11:E94,"Previsto",D11:D94)
A97: TOTAL GERAL A PAGAR (boletos + previsão) | D97: =D95+D96
A99: CONTAS A RECEBER — vendas feitas e ainda não pagas
A100: Espelho das vendas marcadas como "Aguardando Pagamento" nas abas dos meses. Ao receber, mude a Forma de Pagamento na aba do mês E o Status aqui. A linha de conferência avisa se os dois deixarem de bater.
A101: Cliente | B101: Produto / Referência | C101: Data da Venda | D101: Valor (R$) | E101: Status | F101: Dias em Atraso | G101: Observações
A102: Centro de Especialidades Odontomédicas | B102: Refil Everest | C102: 46239 | D102: 140 | E102: Pendente | F102: =IF(OR($E102="Recebido",$C102=""),"",MAX(0,TODAY()-$C102))
A103: Supermercado Brasil | B103: 2x Refil Pro Life | C103: 46239 | D103: 280 | E103: Pendente | F103: =IF(OR($E103="Recebido",$C103=""),"",MAX(0,TODAY()-$C103))
A104: Tropical Motos LTDA | B104: 3x Refil Everest + Refil Pro Life + 3x Pré Filtro + Válvula Reguladora de Pressão | C104: 46245 | D104: 820 | E104: Recebido | F104: =IF(OR($E104="Recebido",$C104=""),"",MAX(0,TODAY()-$C104)) | G104: Recebido via TED em 25/08/2026. NF conferida: valor correto é R$820 (faltava a válvula no lançamento original de R$740).
A105: Free Way | B105: 5x Refil Everest | C105: 46251 | D105: 700 | E105: Recebido | F105: =IF(OR($E105="Recebido",$C105=""),"",MAX(0,TODAY()-$C105)) | G105: Recebido via TED em 02/09/2026.
A106: Neli Sena Rego | B106: Refil Pro Life | C106: 46254 | D106: 140 | E106: Recebido | F106: =IF(OR($E106="Recebido",$C106=""),"",MAX(0,TODAY()-$C106)) | G106: Recebido em dinheiro em 01/09/2026 (R$ 170,00 pelas duas vendas)
A107: Neli Sena Rego | B107: Conexão + Mangueira | C107: 46255 | D107: 40 | E107: Recebido | F107: =IF(OR($E107="Recebido",$C107=""),"",MAX(0,TODAY()-$C107)) | G107: Recebido em dinheiro em 01/09/2026 (R$ 170,00 pelas duas vendas)
A108: Lapec | B108: 4x Refil Everest | C108: 46258 | D108: 480 | E108: Recebido | F108: =IF(OR($E108="Recebido",$C108=""),"",MAX(0,TODAY()-$C108)) | G108: Recebido em dinheiro em 08/09/2026 — lançado em "Set 2026".
A109: Cícero Lima | B109: Refil Everest | C109: 46261 | D109: 140 | E109: Recebido | F109: =IF(OR($E109="Recebido",$C109=""),"",MAX(0,TODAY()-$C109)) | G109: Recebido via Pix em 27/08/2026
A110: Promotoria Regional de Jacobina | B110: 2x Carcaça 9" + 2x Refil Plissado 9" + Conexão Reta Rosca | C110: 46261 | D110: 470 | E110: Recebido | F110: =IF(OR($E110="Recebido",$C110=""),"",MAX(0,TODAY()-$C110)) | G110: Pago em 28/08/2026 em duas formas: R$ 270,00 Pix + R$ 200,00 crédito 2x
A111: Lucas Souza | B111: Refil Everest + Pré Filtro | C111: 46261 | D111: 200 | E111: Recebido | F111: =IF(OR($E111="Recebido",$C111=""),"",MAX(0,TODAY()-$C111)) | G111: Recebido em dinheiro em 03/09/2026 — lançado em "Set 2026".
A112: FG Boa Vista (Recife/PE) | B112: Refis — troca de julho/2026 | C112: 46261 | D112: 1008.8 | E112: Recebido | F112: =IF(OR($E112="Recebido",$C112=""),"",MAX(0,TODAY()-$C112)) | G112: Grupo Ânima — NF 000.004.280 · recebido em 30/08/2026 (Nota Paga no portal V360)
A113: UNIFG Guanambi (Guanambi/BA) | B113: Refis — troca de julho/2026 | C113: 46261 | D113: 4534.75 | E113: Recebido | F113: =IF(OR($E113="Recebido",$C113=""),"",MAX(0,TODAY()-$C113)) | G113: Grupo Ânima — NF 000.004.281 · recebido em 30/08/2026 (Nota Paga no portal V360)
A114: UNP Zona Norte (Natal/RN) | B114: Refis — troca de julho/2026 | C114: 46261 | D114: 870 | E114: Recebido | F114: =IF(OR($E114="Recebido",$C114=""),"",MAX(0,TODAY()-$C114)) | G114: Grupo Ânima — NF 000.004.282 · recebido em 30/08/2026 (Nota Paga no portal V360)
...

Sheet Capital de Giro (BB)
A1: CAPITAL DE GIRO — BANCO DO BRASIL (Empréstimo de Reserva)
A2: Controle de contas da loja pagas pela reserva do Banco do Brasil (não contam como venda/faturamento) e das devoluções feitas pela Planeta Água até quitar o valor.
A3: ← Início
A4: SALDO DEVEDOR (A DEVOLVER) | E4: TOTAL JÁ RETIRADO (HISTÓRICO)
C5: =SUMIF(E9:E200,"A Devolver",D9:D200) | E5: =SUM(D9:D200)
A8: Data | B8: Conta Paga | C8: Categoria Original | D8: Valor (R$) | E8: Status | F8: Data da Devolução | G8: Observações
A9: 46237 | B9: Fracione Transportes | C9: Transporte e Entregas | D9: 1420 | E9: Devolvido | F9: 46265 | G9: Pago via Banco do Brasil — referente Ago 2026
A10: 46237 | B10: Aluguel da Loja | C10: Aluguel | D10: 880 | E10: Devolvido | F10: 46265 | G10: Pago via Banco do Brasil — referente Ago 2026
A11: 46237 | B11: Salário Erick (Estagiário) | C11: Salários, Comissões e Encargos | D11: 600 | E11: Devolvido | F11: 46265 | G11: Pago via Banco do Brasil — referente Ago 2026
A12: 46239 | B12: Filtros Planeta Água | C12: Fornecedores / Mercadoria | D12: 1674.12 | E12: Devolvido | F12: 46265 | G12: Pago via Banco do Brasil — referente Ago 2026
A13: 46238 | B13: Eversoft | C13: Fornecedores / Mercadoria | D13: 980.83 | E13: Devolvido | F13: 46265 | G13: Pago via Banco do Brasil — referente Ago 2026
A14: 46251 | B14: Despesas do dia 17/08/2026 (complemento) | C14: Diversas | D14: 250 | E14: Devolvido | F14: 46265 | G14: Retirada de R$ 250,00 para completar o pagamento das despesas de 17/08 — não corresponde a uma conta específica
A15: 46254 | B15: DAS — Documento de Arrecadação do Simples Nacional | C15: Impostos e Taxas | D15: 2330.53 | E15: Devolvido | F15: 46265 | G15: Pago via Banco do Brasil — referente Ago 2026
A16: 46295 | B16: Knox Produtos Refrigerados (2 bebedouros industriais) | C16: Fornecedores / Mercadoria | D16: 3272 | E16: Devolvido | F16: 46300 | G16: Pago pelo Adriano via Pix do Banco do Brasil com dinheiro da reserva — 30/09/2026. Devolvido em 05/10/2026: a loja transferiu R$ 6.000,00 (conta Ton/Stone → Adriano → Banco do Brasil), sendo R$ 3.272,00 desta devolução e R$ 2.728,00 para a reserva.
A18: Como registrar uma devolução:
A19: 1. Trocar "Status" da linha para "Devolvido" e preencher a "Data da Devolução".
A20: 2. Só isso. NÃO lançar a devolução como Saída na aba do mês — a despesa já foi lançada uma vez lá. Enquanto o status for "A Devolver", o valor é descontado do total de Despesas do mês (linha "Capital de Giro (BB) — ainda a devolver" do pivô); ao virar "Devolvido", passa a contar normalmente.

Sheet Ponto de Equilíbrio
A1: PONTO DE EQUILÍBRIO
A2: Quanto a loja precisa faturar por mês para pagar todas as contas E o pró-labore da Edilânia, sem prejuízo. Base: média dos meses já fechados em 2026 (o mês em andamento só entra na média quando terminar).
A3: ← Início
A4: Indicador | B4: Valor
A5: Receita média mensal | B5: ='DRE Simplificado'!O5
A6: Custos variáveis médios | B6: ='DRE Simplificado'!O10
A7: Margem de contribuição média (R$) | B7: ='DRE Simplificado'!O11
A8: Margem de contribuição (%) | B8: =IF(B5=0,"",B7/B5)
A9: Custos fixos da loja (média por mês) | B9: ='DRE Simplificado'!O23
A10: Pró-labore combinado da Edilânia (por mês) | B10: 4000 | C10: ← valor combinado em 05/10/2026. Se o combinado mudar, troque só aqui — a planilha e o site usam este número.
A11: Total a pagar por mês (custos fixos + pró-labore) | B11: =B9+B10
A12: PONTO DE EQUILÍBRIO (faturamento mínimo/mês, já pagando o pró-labore) | B12: =IF(B8<=0,"",B11/B8)
A13: Sobra média da loja ANTES do pró-labore | B13: ='DRE Simplificado'!O24
A14: Sobra média DEPOIS do pró-labore combinado | B14: =B13-B10
A16: Ticket médio da loja (preencha) | B16: 140 | C16: ← valor médio de uma venda. Serve para converter R$ em nº de vendas.
A18: QUANTO PRECISO VENDER PARA...
A19: Objetivo | B19: Lucro desejado (R$) — além do pró-labore | C19: Faturamento necessário (R$) | D19: Nº de vendas no mês | E19: Vendas por dia útil (26 dias)
A20: Pagar tudo e a Edilânia (sem prejuízo) | B20: 0 | C20: =IF($B$8<=0,"",($B$11+B20)/$B$8) | D20: =IF(OR($B$8<=0,$B$16=0),"",ROUNDUP(C20/$B$16,0)) | E20: =IF(D20="","",ROUND(D20/26,1))
A21: Lucrar R$ 500 | B21: 500 | C21: =IF($B$8<=0,"",($B$11+B21)/$B$8) | D21: =IF(OR($B$8<=0,$B$16=0),"",ROUNDUP(C21/$B$16,0)) | E21: =IF(D21="","",ROUND(D21/26,1))
A22: Lucrar R$ 1.000 | B22: 1000 | C22: =IF($B$8<=0,"",($B$11+B22)/$B$8) | D22: =IF(OR($B$8<=0,$B$16=0),"",ROUNDUP(C22/$B$16,0)) | E22: =IF(D22="","",ROUND(D22/26,1))
A23: Lucrar R$ 2.000 | B23: 2000 | C23: =IF($B$8<=0,"",($B$11+B23)/$B$8) | D23: =IF(OR($B$8<=0,$B$16=0),"",ROUNDUP(C23/$B$16,0)) | E23: =IF(D23="","",ROUND(D23/26,1))
A24: Lucrar R$ 3.000 | B24: 3000 | C24: =IF($B$8<=0,"",($B$11+B24)/$B$8) | D24: =IF(OR($B$8<=0,$B$16=0),"",ROUNDUP(C24/$B$16,0)) | E24: =IF(D24="","",ROUND(D24/26,1))
A25: Lucrar R$ 5.000 | B25: 5000 | C25: =IF($B$8<=0,"",($B$11+B25)/$B$8) | D25: =IF(OR($B$8<=0,$B$16=0),"",ROUNDUP(C25/$B$16,0)) | E25: =IF(D25="","",ROUND(D25/26,1))
A27: =IF(B8<=0,"⚠ ATENÇÃO: a margem de contribuição está negativa ou zerada — os custos variáveis estão consumindo toda a receita. Enquanto isso não for corrigido (preço, frete ou custo de compra), não existe ponto de equilíbrio possível.","✔ Margem de contribuição positiva: cada R$ 100 vendidos deixam R$ "&TEXT(B8*100,"0.00")&" para pagar os custos fixos, o pró-labore e gerar lucro.")
A28: O pró-labore da Edilânia é tudo o que ela gasta do dinheiro da loja (categoria "Pro Labore Edilânia" nas abas dos meses). Por isso ele entra aqui como uma conta fixa: a loja só está "no zero a zero" quando paga todas as despesas E os R$ combinados com ela.

Sheet Fluxo de Caixa Projetado
A1: FLUXO DE CAIXA PROJETADO
A2: Projeção do saldo dos próximos meses. As previsões vêm da média dos meses já fechados; edite as células amarelas com o que você já sabe que vai entrar ou sair.
A3: ← Início
A4: Saldo de caixa hoje (preencha) | B4: 0 | C4: ← quanto existe de dinheiro em caixa + banco nesta data
A6: Mês | B6: Entradas Previstas (R$) | C6: Recebimentos de Contas a Receber (R$) | D6: Saídas Previstas (R$) | E6: Resultado do Mês (R$) | F6: Saldo Acumulado (R$)
A7: Setembro/2026 | B7: ='DRE Simplificado'!O5 | C7: ='Contas a Pagar e Receber'!C5 | D7: =('DRE Simplificado'!O10+'DRE Simplificado'!O23+'Ponto de Equilíbrio'!$B$10) | E7: =B7+C7-D7 | F7: =$B$4+E7
A8: Outubro/2026 | B8: ='DRE Simplificado'!O5 | C8: 0 | D8: =('DRE Simplificado'!O10+'DRE Simplificado'!O23+'Ponto de Equilíbrio'!$B$10) | E8: =B8+C8-D8 | F8: =F7+E8
A9: Novembro/2026 | B9: ='DRE Simplificado'!O5 | C9: 0 | D9: =('DRE Simplificado'!O10+'DRE Simplificado'!O23+'Ponto de Equilíbrio'!$B$10) | E9: =B9+C9-D9 | F9: =F8+E9
A10: Dezembro/2026 | B10: ='DRE Simplificado'!O5 | C10: 0 | D10: =('DRE Simplificado'!O10+'DRE Simplificado'!O23+'Ponto de Equilíbrio'!$B$10) | E10: =B10+C10-D10 | F10: =F9+E10
A12: TOTAL PROJETADO | B12: =SUM(B7:B10) | C12: =SUM(C7:C10) | D12: =SUM(D7:D10) | E12: =SUM(E7:E10) | F12: =F10
A14: =IF(F10<0,"⚠ Pelo ritmo atual, o caixa fica NEGATIVO até dezembro. Reveja despesas fixas ou acelere a cobrança do que está a receber.","✔ Pelo ritmo atual, o caixa se mantém positivo até dezembro.")
A16: Saídas previstas = custos variáveis médios + custos fixos médios (aba DRE) + pró-labore combinado da Edilânia. As contas a receber pendentes entram uma única vez, em setembro, pois são vendas já feitas.

Sheet Reserva e Impostos
A1: RESERVA DE EMERGÊNCIA E IMPOSTOS
A2: Quanto a loja precisa ter guardado para aguentar meses ruins, e quanto sai de imposto por mês.
A3: ← Início
A4: RESERVA DE EMERGÊNCIA
A5: Indicador | B5: Valor
A6: Custo fixo médio mensal + pró-labore combinado da Edilânia | B6: ='DRE Simplificado'!O23+'Ponto de Equilíbrio'!$B$10
A7: Meses de cobertura desejados | B7: 3 | C7: ← 3 meses é o padrão recomendado para pequeno comércio
A8: RESERVA IDEAL | B8: =B6*B7
A9: Reserva que já existe hoje | B9: 28728 | C9: Aporte de Adriano em 03/09/2026: R$ 17.000,00 (R$ 8.135,48 desse valor quitou o saldo devedor do Capital de Giro (BB) — como o Capital de Giro É a reserva do Banco do Brasil, esse dinheiro voltou para a própria reserva ao quitar a dívida). Em 09/09/2026, retirada de R$ 6.500,00 do caixa da loja para a reserva — transferência entre contas da empresa, por isso não foi lançada como saída nas abas mensais. Pix do BNB para Adriano guardados como reserva (confirmado pela Edilânia em 30/09/2026): R$ 500,00 em 11/09 e R$ 2.000,00 em 25/09. Em 30/09/2026 saíram R$ 3.272,00 da reserva para pagar 2 bebedouros industriais da Knox (a loja deve devolver — ver aba Capital de Giro (BB)). Em 05/10/2026 a loja transferiu R$ 6.000,00 para a reserva no Banco do Brasil (via Pix para o Adriano): R$ 3.272,00 devolvendo o que a reserva pagou à Knox + R$ 2.728,00 a mais guardados. Total guardado: R$ 28.728,00. Em aberto: Pix de R$ 2.000,00 para Adriano em 09/09 — confirmar se já faz parte dos R$ 6.500,00 do mesmo dia.
A10: Falta guardar | B10: =MAX(0,B8-B9)
A11: Meses de cobertura que você tem hoje | B11: =IF(B6=0,"",B9/B6)
A14: IMPOSTOS
A15: Item | B15: Valor
A16: Regime tributário | B16: Simples Nacional
A17: Alíquota efetiva (%) | B17: 0.06
A18: Faturamento médio mensal | B18: ='DRE Simplificado'!O5
A19: Imposto estimado por mês | B19: =B18*B17
A20: Imposto estimado no ano (12 meses) | B20: =B19*12
A21: Dia de vencimento da guia (DAS) | B21: 20
A23: Regime e alíquota são um chute inicial — confirme com seu contador. O imposto já pago aparece nas abas mensais na categoria 'Impostos e Taxas'.
A24: A reserva ideal cobre os custos fixos E o pró-labore da Edilânia. Se quiser cobrir também a compra de mercadoria, aumente os meses de cobertura.

Sheet Orçado vs Realizado
A1: ORÇADO vs REALIZADO — AGOSTO/2026
A2: Defina a meta (amarelo) e compare com o que realmente aconteceu. O realizado é puxado automaticamente da aba do mês.
A3: ← Início
A4: Item | B4: Orçado (R$) | C4: Realizado (R$) | D4: Diferença (R$) | E4: % da Meta | F4: Situação
A5: FATURAMENTO | B5: 15000 | C5: =SUMIF('Ago 2026'!E5:E500,"<>",'Ago 2026'!D5:D500)-SUMIF('Ago 2026'!E5:E500,"<>",'Ago 2026'!F5:F500)-'Ago 2026'!T5 | D5: =C5-B5 | E5: =IF(B5=0,"",C5/B5) | F5: =IF(B5=0,"",IF(C5>=B5,"✔ Meta atingida","Faltam "&TEXT(B5-C5,"R$ #,##0.00")))
A7: DESPESAS POR CATEGORIA
A8: Categoria | B8: Orçado (R$) | C8: Realizado (R$) | D8: Diferença (R$) | E8: % da Meta | F8: Situação
A9: Fornecedores / Mercadoria | C9: ='Ago 2026'!L5 | D9: =C9-B9 | E9: =IF(B9=0,"",C9/B9) | F9: =IF(B9=0,"",IF(C9<=B9,"✔ Dentro do orçado","Estourou "&TEXT(C9-B9,"R$ #,##0.00")))
A10: Aluguel | C10: ='Ago 2026'!L6 | D10: =C10-B10 | E10: =IF(B10=0,"",C10/B10) | F10: =IF(B10=0,"",IF(C10<=B10,"✔ Dentro do orçado","Estourou "&TEXT(C10-B10,"R$ #,##0.00")))
A11: Água, Energia e Internet | C11: ='Ago 2026'!L7 | D11: =C11-B11 | E11: =IF(B11=0,"",C11/B11) | F11: =IF(B11=0,"",IF(C11<=B11,"✔ Dentro do orçado","Estourou "&TEXT(C11-B11,"R$ #,##0.00")))
A12: Impostos e Taxas | C12: ='Ago 2026'!L8 | D12: =C12-B12 | E12: =IF(B12=0,"",C12/B12) | F12: =IF(B12=0,"",IF(C12<=B12,"✔ Dentro do orçado","Estourou "&TEXT(C12-B12,"R$ #,##0.00")))
A13: Tarifas Bancárias e Cartão | C13: ='Ago 2026'!L9 | D13: =C13-B13 | E13: =IF(B13=0,"",C13/B13) | F13: =IF(B13=0,"",IF(C13<=B13,"✔ Dentro do orçado","Estourou "&TEXT(C13-B13,"R$ #,##0.00")))
A14: Transporte e Entregas | C14: ='Ago 2026'!L10 | D14: =C14-B14 | E14: =IF(B14=0,"",C14/B14) | F14: =IF(B14=0,"",IF(C14<=B14,"✔ Dentro do orçado","Estourou "&TEXT(C14-B14,"R$ #,##0.00")))
A15: Salários, Comissões e Encargos | C15: ='Ago 2026'!L11 | D15: =C15-B15 | E15: =IF(B15=0,"",C15/B15) | F15: =IF(B15=0,"",IF(C15<=B15,"✔ Dentro do orçado","Estourou "&TEXT(C15-B15,"R$ #,##0.00")))
A16: Contabilidade | C16: ='Ago 2026'!L12 | D16: =C16-B16 | E16: =IF(B16=0,"",C16/B16) | F16: =IF(B16=0,"",IF(C16<=B16,"✔ Dentro do orçado","Estourou "&TEXT(C16-B16,"R$ #,##0.00")))
A17: Manutenção e Reparos | C17: ='Ago 2026'!L13 | D17: =C17-B17 | E17: =IF(B17=0,"",C17/B17) | F17: =IF(B17=0,"",IF(C17<=B17,"✔ Dentro do orçado","Estourou "&TEXT(C17-B17,"R$ #,##0.00")))
A18: Material de Limpeza e Escritório | C18: ='Ago 2026'!L14 | D18: =C18-B18 | E18: =IF(B18=0,"",C18/B18) | F18: =IF(B18=0,"",IF(C18<=B18,"✔ Dentro do orçado","Estourou "&TEXT(C18-B18,"R$ #,##0.00")))
A19: Estornos de Vendas (Cancelamentos) | C19: ='Ago 2026'!L15 | D19: =C19-B19 | E19: =IF(B19=0,"",C19/B19) | F19: =IF(B19=0,"",IF(C19<=B19,"✔ Dentro do orçado","Estourou "&TEXT(C19-B19,"R$ #,##0.00")))
A20: Outras Despesas | C20: ='Ago 2026'!L16 | D20: =C20-B20 | E20: =IF(B20=0,"",C20/B20) | F20: =IF(B20=0,"",IF(C20<=B20,"✔ Dentro do orçado","Estourou "&TEXT(C20-B20,"R$ #,##0.00")))
A21: TOTAL DESPESAS | B21: =SUM(B9:B20) | C21: =SUM(C9:C20) | D21: =C21-B21 | E21: =IF(B21=0,"",C21/B21)
A22: Pró-labore Edilânia (combinado) | B22: ='Ponto de Equilíbrio'!$B$10 | C22: ='Ago 2026'!L17 | D22: =C22-B22 | E22: =IF(B22=0,"",C22/B22) | F22: =IF(B22=0,"",IF(C22<=B22,"✔ Dentro do combinado","Passou "&TEXT(C22-B22,"R$ #,##0.00")))
A23: RESULTADO (Faturamento − Despesas − Pró-labore) | B23: =B5-B21-B22 | C23: =C5-C21-C22 | D23: =C23-B23
A25: Preencha as metas nas células amarelas. Para usar em outro mês, troque as referências 'Ago 2026' pelas do mês desejado (ex.: 'Set 2026'), mantendo as mesmas linhas do quadro Saídas por Categoria.

Sheet Precificação e Margem
A1: PRECIFICAÇÃO E MARGEM POR PRODUTO
A2: Quanto sobra de verdade em cada item vendido. Custo = última compra de 2026 (IPI incluso, Simples não recupera) + 6,4% de frete de entrada nos itens da Everest e Eversoft, que são FOB. Filtros Planeta Água, Culligan e Knox são CIF: frete já vem no preço.
A3: ← Início
A4: Taxa média de cartão | B4: 0.07 | C4: Alíquota de imposto | D4: 0.06 | E4: ← taxa dos itens de balcão. Purificadores usam 13,99% (crédito 10x) direto na fórmula; Baby usa 11% (6x).
A5: COMISSÃO: só entra quando o Wiliam faz a troca/instalação. Venda de balcão sem serviço = margem R$ 10 (ou R$ 30) maior. Refis de outras marcas ficam sem comissão porque raramente são trocados por ele. A tabela lista só o que é comprado e revendido — serviços avulsos (instalação por fora, limpeza de refil) saíram daqui em 10/09/2026 por serem raros.
A6: Produto / Serviço | B6: Preço de Venda (R$) | C6: Custo de Aquisição (R$) | D6: Comissão (R$) | E6: Taxa de Cartão (R$) | F6: Imposto (R$) | G6: Custo Total (R$) | H6: Margem Líquida (R$) | I6: Margem (%) | J6: Taxa aplicada
A7: Refil Everest | B7: 140 | C7: 46.76 | D7: 10 | E7: =IF(B7="","",B7*IF($J7="",$B$4,$J7)) | F7: =IF(B7="","",B7*$D$4) | G7: =IF(B7="","",SUM(C7:F7)) | H7: =IF(B7="","",B7-G7) | I7: =IF(B7=0,"",H7/B7)
A8: Refil Pro Life | B8: 140 | C8: 24.2 | D8: 10 | E8: =IF(B8="","",B8*IF($J8="",$B$4,$J8)) | F8: =IF(B8="","",B8*$D$4) | G8: =IF(B8="","",SUM(C8:F8)) | H8: =IF(B8="","",B8-G8) | I8: =IF(B8=0,"",H8/B8)
A9: Refil Carbon Tech 9" | B9: 85 | C9: 32.48 | D9: 0 | E9: =IF(B9="","",B9*IF($J9="",$B$4,$J9)) | F9: =IF(B9="","",B9*$D$4) | G9: =IF(B9="","",SUM(C9:F9)) | H9: =IF(B9="","",B9-G9) | I9: =IF(B9=0,"",H9/B9)
A10: Refil Carbon Tech 5" | B10: 60 | C10: 34.41 | D10: 0 | E10: =IF(B10="","",B10*IF($J10="",$B$4,$J10)) | F10: =IF(B10="","",B10*$D$4) | G10: =IF(B10="","",SUM(C10:F10)) | H10: =IF(B10="","",B10-G10) | I10: =IF(B10=0,"",H10/B10)
A11: Refil E3 | B11: 110 | C11: 20.17 | D11: 0 | E11: =IF(B11="","",B11*IF($J11="",$B$4,$J11)) | F11: =IF(B11="","",B11*$D$4) | G11: =IF(B11="","",SUM(C11:F11)) | H11: =IF(B11="","",B11-G11) | I11: =IF(B11=0,"",H11/B11)
A12: Refil Plissado | B12: 80 | C12: 20.26 | D12: 0 | E12: =IF(B12="","",B12*IF($J12="",$B$4,$J12)) | F12: =IF(B12="","",B12*$D$4) | G12: =IF(B12="","",SUM(C12:F12)) | H12: =IF(B12="","",B12-G12) | I12: =IF(B12=0,"",H12/B12)
A13: Refil C+3 (IBBL) | B13: 115 | C13: 24 | D13: 0 | E13: =IF(B13="","",B13*IF($J13="",$B$4,$J13)) | F13: =IF(B13="","",B13*$D$4) | G13: =IF(B13="","",SUM(C13:F13)) | H13: =IF(B13="","",B13-G13) | I13: =IF(B13=0,"",H13/B13)
A14: Pré Filtro | B14: 60 | C14: 10.84 | D14: 0 | E14: =IF(B14="","",B14*IF($J14="",$B$4,$J14)) | F14: =IF(B14="","",B14*$D$4) | G14: =IF(B14="","",SUM(C14:F14)) | H14: =IF(B14="","",B14-G14) | I14: =IF(B14=0,"",H14/B14)
A15: Mangueira (por metro) | B15: 10 | C15: 1.72 | D15: 0 | E15: =IF(B15="","",B15*IF($J15="",$B$4,$J15)) | F15: =IF(B15="","",B15*$D$4) | G15: =IF(B15="","",SUM(C15:F15)) | H15: =IF(B15="","",B15-G15) | I15: =IF(B15=0,"",H15/B15)
A16: Registro | B16: 30 | C16: 5.19 | D16: 0 | E16: =IF(B16="","",B16*IF($J16="",$B$4,$J16)) | F16: =IF(B16="","",B16*$D$4) | G16: =IF(B16="","",SUM(C16:F16)) | H16: =IF(B16="","",B16-G16) | I16: =IF(B16=0,"",H16/B16)
A17: Termostato | B17: 170 | C17: 45 | D17: 30 | E17: =IF(B17="","",B17*IF($J17="",$B$4,$J17)) | F17: =IF(B17="","",B17*$D$4) | G17: =IF(B17="","",SUM(C17:F17)) | H17: =IF(B17="","",B17-G17) | I17: =IF(B17=0,"",H17/B17)
A18: Purificador Everest Slim Branco | B18: 1429 | C18: 715.02 | D18: 30 | E18: =IF(B18="","",B18*IF($J18="",$B$4,$J18)) | F18: =IF(B18="","",B18*$D$4) | G18: =IF(B18="","",SUM(C18:F18)) | H18: =IF(B18="","",B18-G18) | I18: =IF(B18=0,"",H18/B18) | J18: 0.1399
A19: Purificador Everest Slim Prata | B19: 1486 | C19: 784.97 | D19: 30 | E19: =IF(B19="","",B19*IF($J19="",$B$4,$J19)) | F19: =IF(B19="","",B19*$D$4) | G19: =IF(B19="","",SUM(C19:F19)) | H19: =IF(B19="","",B19-G19) | I19: =IF(B19=0,"",H19/B19) | J19: 0.1399
A20: Purificador Everest Star Branco | B20: 1429 | C20: 756.73 | D20: 30 | E20: =IF(B20="","",B20*IF($J20="",$B$4,$J20)) | F20: =IF(B20="","",B20*$D$4) | G20: =IF(B20="","",SUM(C20:F20)) | H20: =IF(B20="","",B20-G20) | I20: =IF(B20=0,"",H20/B20) | J20: 0.1399
A21: Purificador Everest Plus Branco | B21: 1529 | C21: 820.73 | D21: 30 | E21: =IF(B21="","",B21*IF($J21="",$B$4,$J21)) | F21: =IF(B21="","",B21*$D$4) | G21: =IF(B21="","",SUM(C21:F21)) | H21: =IF(B21="","",B21-G21) | I21: =IF(B21=0,"",H21/B21) | J21: 0.1399
A22: Purificador Everest Plus Prata | B22: 1569 | C22: 906.93 | D22: 30 | E22: =IF(B22="","",B22*IF($J22="",$B$4,$J22)) | F22: =IF(B22="","",B22*$D$4) | G22: =IF(B22="","",SUM(C22:F22)) | H22: =IF(B22="","",B22-G22) | I22: =IF(B22=0,"",H22/B22) | J22: 0.1399
A23: Purificador Everest Fit Branco | B23: 1429 | C23: 756.73 | D23: 30 | E23: =IF(B23="","",B23*IF($J23="",$B$4,$J23)) | F23: =IF(B23="","",B23*$D$4) | G23: =IF(B23="","",SUM(C23:F23)) | H23: =IF(B23="","",B23-G23) | I23: =IF(B23=0,"",H23/B23) | J23: 0.1399
A24: Purificador Everest Fit Preto | B24: 1486 | C24: 784.96 | D24: 30 | E24: =IF(B24="","",B24*IF($J24="",$B$4,$J24)) | F24: =IF(B24="","",B24*$D$4) | G24: =IF(B24="","",SUM(C24:F24)) | H24: =IF(B24="","",B24-G24) | I24: =IF(B24=0,"",H24/B24) | J24: 0.1399
A25: Purificador Everest Fit Prata | B25: 1486 | C25: 739.37 | D25: 30 | E25: =IF(B25="","",B25*IF($J25="",$B$4,$J25)) | F25: =IF(B25="","",B25*$D$4) | G25: =IF(B25="","",SUM(C25:F25)) | H25: =IF(B25="","",B25-G25) | I25: =IF(B25=0,"",H25/B25) | J25: 0.1399
A26: Purificador Everest Star Preto | B26: 1486 | C26: 784.96 | D26: 30 | E26: =IF(B26="","",B26*IF($J26="",$B$4,$J26)) | F26: =IF(B26="","",B26*$D$4) | G26: =IF(B26="","",SUM(C26:F26)) | H26: =IF(B26="","",B26-G26) | I26: =IF(B26=0,"",H26/B26) | J26: 0.1399
A27: Purificador Everest Foz Branco | B27: 1589 | C27: 767.95 | D27: 30 | E27: =IF(B27="","",B27*IF($J27="",$B$4,$J27)) | F27: =IF(B27="","",B27*$D$4) | G27: =IF(B27="","",SUM(C27:F27)) | H27: =IF(B27="","",B27-G27) | I27: =IF(B27=0,"",H27/B27) | J27: 0.1399
A28: Purificador Everest Foz Cinza/Grafite | B28: 1689 | C28: 819.57 | D28: 30 | E28: =IF(B28="","",B28*IF($J28="",$B$4,$J28)) | F28: =IF(B28="","",B28*$D$4) | G28: =IF(B28="","",SUM(C28:F28)) | H28: =IF(B28="","",B28-G28) | I28: =IF(B28=0,"",H28/B28) | J28: 0.1399
A29: Purificador Everest Baby (todas as cores) | B29: 420 | C29: 150.13 | D29: 30 | E29: =IF(B29="","",B29*IF($J29="",$B$4,$J29)) | F29: =IF(B29="","",B29*$D$4) | G29: =IF(B29="","",SUM(C29:F29)) | H29: =IF(B29="","",B29-G29) | I29: =IF(B29=0,"",H29/B29) | J29: 0.11
